Workbook

Sheet Read Me
A1: Pre-Construction Commercial Register
A2: What this is | B2: The 175 retained items in your pre-construction commercial pack, mapped into the purpose-built folder structure. The 55 documents marked as not required were removed from the stage checklists and Master Register.
A3: Why a new tree | B3: Your earlier folder structure was designed for the construction/delivery phase (Monthly Management, Subcontractor valuations, Close Out). It doesn't fit a pre-construction pack — half its folders would be empty and many pre-con documents had no home. This tree fixes that. Your construction-phase tree is untouched; use it once the job starts on site.
A4: Sheets | B4: Stage 1 / 2 / 3 — updated phase checklists (Bid, Award, Pre-Con). / Master Register — all 175 retained items with folder columns (T–Y). / Pre-Con Folder Structure and Folder Coverage — live counts by folder. / Dashboard — live totals and workstream analysis.
A5: Naming | B5: PROJ-MCR-CM-[TYPE]-[####]_[Title]. Every folder has a unique TYPE code (no collisions). Set the real project code per job — find-and-replace PROJ in column W.
A6: Stages vs folders | B6: Folder = where a document lives for its whole life (fixed). Stage = which phase it must be cleared by (a filter). They're independent, so nothing gets renamed as it moves between Stages.
A7: Owners | B7: Mapped to your four-person team (Samar / Javeria / Madiha), with CM approving all.
A8: Still to confirm | B8: Confirm whether the retained Project Bank Account / Escrow Requirements item belongs in folder 6.30; the struck tax, CIS and credit-risk documents have been removed.

Sheet Stage 1 - Bid & Tender
A1: Stage 1 - Bid & Tender
A2: =COUNTA(A6:A16)&" items · "&COUNTIF(E6:E16,"Critical")&" Critical · "&COUNTIF(C6:C16,"Yes*")&" go to client" -> 11 items · 8 Critical · 4 go to client
A3: Everything needed to win the main contract. Only the shaded 'goes to client' rows physically go out; the rest are internal tender records kept as the priced baseline.
A5: Ref | B5: Document / Control | C5: Goes to client? | D5: Workstream | E5: Priority | F5: Stage / Stage | G5: Folder (L1 › L2) | H5: TYPE | I5: Proposed File Name | J5: Owner
A6: PC-A-001 | B6: Client ITT / Tender Documents (as issued) | C6: Internal record | D6: Tender & Bid Baseline | E6: Critical | F6: Tender receipt | G6: 1.0 › 1.10 Tender Source Information (Frozen) | H6: TSI | I6: PROJ-MCR-CM-TSI-0001_ClientITT | J6: QS
A7: PC-A-002 | B7: Tender Addenda / Bulletin Register | C7: Internal record | D7: Tender & Bid Baseline | E7: Critical | F7: Tender period | G7: 1.0 › 1.10 Tender Source Information (Frozen) | H7: TSI | I7: PROJ-MCR-CM-TSI-0004_TenderAddenda | J7: QS
A8: PC-A-003 | B8: Tender Clarifications and RFI Log | C8: Internal record | D8: Tender & Bid Baseline | E8: Critical | F8: Tender period | G8: 1.0 › 1.10 Tender Source Information (Frozen) | H8: TSI | I8: PROJ-MCR-CM-TSI-0005_TenderClarificationsRFILog | J8: QS
A9: PC-A-006 | B9: Priced Tender Submission (full build-up) | C9: Yes — goes to client | D9: Tender & Bid Baseline | E9: Critical | F9: Tender submission | G9: 1.0 › 1.20 Priced Bid & Assumptions | H9: BID | I9: PROJ-MCR-CM-BID-0001_PricedTenderSubmission | J9: QS
A10: PC-A-007 | B10: Tender Qualifications, Exclusions and Assumptions Schedule | C10: Yes — goes to client | D10: Tender & Bid Baseline | E10: Critical | F10: Tender submission | G10: 1.0 › 1.30 Bid Governance & Submission | H10: BGV | I10: PROJ-MCR-CM-BGV-0001_TenderQualifications | J10: QS
A11: PC-A-008 | B11: Tender Baseline Programme | C11: Yes — goes to client | D11: Tender & Bid Baseline | E11: Critical | F11: Tender submission | G11: 1.0 › 1.30 Bid Governance & Submission | H11: BGV | I11: PROJ-MCR-CM-BGV-0002_TenderBaselineProgramme | J11: QS
A12: PC-A-009 | B12: Tender Adjudication / Settlement Summary | C12: Internal record | D12: Tender & Bid Baseline | E12: Critical | F12: Tender submission | G12: 1.0 › 1.30 Bid Governance & Submission | H12: BGV | I12: PROJ-MCR-CM-BGV-0003_TenderAdjudication | J12: QS
A13: PC-A-010 | B13: Tender Risk and Opportunity Schedule | C13: Internal record | D13: Tender & Bid Baseline | E13: Critical | F13: Tender submission | G13: 1.0 › 1.30 Bid Governance & Submission | H13: BGV | I13: PROJ-MCR-CM-BGV-0004_TenderRiskOpportunitySchedule | J13: QS
A14: PC-A-004 | B14: Site Visit / Existing Conditions Record | C14: Internal record | D14: Tender & Bid Baseline | E14: High | F14: Tender period | G14: 1.0 › 1.10 Tender Source Information (Frozen) | H14: TSI | I14: PROJ-MCR-CM-TSI-0006_SiteVisit | J14: QS
A15: PC-A-005 | B15: Tender Return Requirements Checklist | C15: Internal record | D15: Tender & Bid Baseline | E15: High | F15: Tender period | G15: 1.0 › 1.10 Tender Source Information (Frozen) | H15: TSI | I15: PROJ-MCR-CM-TSI-0007_TenderReturnRequirementsChecklist | J15: QS
A16: PC-A-011 | B16: Bid Bonds / Tender Security Record | C16: Yes — goes to client | D16: Tender & Bid Baseline | E16: High | F16: Tender submission | G16: 1.0 › 1.30 Bid Governance & Submission | H16: BGV | I16: PROJ-MCR-CM-BGV-0005_BidBonds | J16: QS

Sheet Stage 2 - Contract Award
A1: Stage 2 - Contract Award
A2: =COUNTA(A6:A24)&" items · "&COUNTIF(D6:D24,"Critical")&" Critical" -> 19 items · 14 Critical
A3: Everything to close and sign — including cross-cutting items (LADs, insurance exclusions, ground risk, S106, funding) that must be resolved before execution.
A5: Ref | B5: Document / Control | C5: Workstream | D5: Priority | E5: Stage / Stage | F5: Folder (L1 › L2) | G5: TYPE | H5: Proposed File Name | I5: Owner
A6: PC-B-001 | B6: Contract-vs-Tender Reconciliation | C6: Contract Formation | D6: Critical | E6: Pre-contract | F6: 2.0 › 2.20 Tender-to-Contract Reconciliation | G6: T2C | H6: PROJ-MCR-CM-T2C-0001_ContractVsTenderReconciliation | I6: CM
A7: PC-B-002 | B7: Executed Building Contract | C7: Contract Formation | D7: Critical | E7: Contract execution | F7: 2.0 › 2.10 Executed Contract & Particulars | G7: CON | H7: PROJ-MCR-CM-CON-0001_ExecutedBuildingContract | I7: CM
A8: PC-B-003 | B8: Contract Particulars Register | C8: Contract Formation | D8: Critical | E8: Contract execution | F8: 2.0 › 2.10 Executed Contract & Particulars | G8: CON | H8: PROJ-MCR-CM-CON-0002_ContractParticularsRegister | I8: CM
A9: PC-B-004 | B9: Contractor’s Proposals Register | C9: Contract Formation | D9: Critical | E9: Pre-contract | F9: 2.0 › 2.40 ER / CP & Compliance | G9: ERCP | H9: PROJ-MCR-CM-ERCP-0002_ContractorSProposalsRegister | I9: PCC
A10: PC-B-005 | B10: ER/CP Compliance and Divergence Matrix | C10: Contract Formation | D10: Critical | E10: Pre-contract | F10: 2.0 › 2.40 ER / CP & Compliance | G10: ERCP | H10: PROJ-MCR-CM-ERCP-0003_ER | I10: PCC
A11: PC-B-006 | B11: Contract Sum Analysis / Contract Sum Breakdown | C11: Contract Formation | D11: Critical | E11: Contract execution | F11: 2.0 › 2.60 Contract Pricing Basis | G11: CPB | H11: PROJ-MCR-CM-CPB-0001_ContractSumAnalysis | I11: QS
A12: PC-B-007 | B12: Pricing Document / Bill of Quantities / Schedule of Rates | C12: Contract Formation | D12: Critical | E12: Contract execution | F12: 2.0 › 2.60 Contract Pricing Basis | G12: CPB | H12: PROJ-MCR-CM-CPB-0002_PricingDocument | I12: QS
A13: PC-B-008 | B13: Contract Data / Scope / Works Information (NEC where applicable) | C13: Contract Formation | D13: Critical | E13: Contract execution | F13: 2.0 › 2.10 Executed Contract & Particulars | G13: CON | H13: PROJ-MCR-CM-CON-0004_ContractData | I13: CM
A14: PC-B-009 | B14: Letter of Intent Register and Authority | C14: Contract Formation | D14: Critical | E14: Pre-contract | F14: 2.0 › 2.30 Contract Risk & Liabilities | G14: CRL | H14: PROJ-MCR-CM-CRL-0001_LetterIntentRegisterAuthority | I14: CM
A15: PC-B-011 | B15: Contract Approval / DeleStaged Authority Sign-Off | C15: Contract Formation | D15: Critical | E15: Before execution | F15: 2.0 › 2.20 Tender-to-Contract Reconciliation | G15: T2C | H15: PROJ-MCR-CM-T2C-0004_ContractApproval | I15: CM
A16: PC-B-012 | B16: Key Contract Dates and Notices Schedule | C16: Contract Formation | D16: Critical | E16: Contract execution | F16: 2.0 › 2.10 Executed Contract & Particulars | G16: CON | H16: PROJ-MCR-CM-CON-0005_KeyContractDatesNoticesSchedule | I16: CM
... A24: PC-M-002 | B24: Section 106 / Community Infrastructure Levy Schedule | C24: Property, Statutory & Third Parties | D24: High | E24: Pre-contract | F24: 10.0 › 10.10 Planning & Statutory Obligations | G24: STA | H24: PROJ-MCR-CM-STA-0002_Section106 | I24: PCC

Sheet Stage 3 - Pre-Construction
A1: Stage 3 - Pre-Construction
A2: =COUNTA(A6:A150)&" items · "&COUNTIF(D6:D150,"Critical")&" Critical" -> 145 items · 69 Critical
A3: Everything to get ready to build once won. Almost all internal.
A5: Ref | B5: Document / Control | C5: Workstream | D5: Priority | E5: Stage / Stage | F5: Folder (L1 › L2) | G5: TYPE | H5: Proposed File Name | I5: Owner
A6: PC-C-001 | B6: Project Scope Responsibility Matrix | C6: Scope & Design Cost Control | D6: Critical | E6: Pre-construction | F6: 3.0 › 3.10 Scope Definition & Interfaces | G6: SCP | H6: PROJ-MCR-CM-SCP-0001_ProjectScopeResponsibilityMatrix | I6: PCC
A7: PC-C-002 | B7: Subcontract Package Matrix | C7: Scope & Design Cost Control | D7: Critical | E7: Pre-construction | F7: 3.0 › 3.10 Scope Definition & Interfaces | G7: SCP | H7: PROJ-MCR-CM-SCP-0002_SubcontractPackageMatrix | I7: PCC
A8: PC-C-003 | B8: Package Interface Matrix | C8: Scope & Design Cost Control | D8: Critical | E8: Pre-construction | F8: 3.0 › 3.10 Scope Definition & Interfaces | G8: SCP | H8: PROJ-MCR-CM-SCP-0003_PackageInterfaceMatrix | I8: PCC
A9: PC-C-004 | B9: Design-to-Cost Tracker | C9: Scope & Design Cost Control | D9: Critical | E9: Design development | F9: 3.0 › 3.30 Design Cost Control | G9: DCC | H9: PROJ-MCR-CM-DCC-0001_DesignCostTracker | I9: QS
A10: PC-C-005 | B10: Cost Check at Design Stage | C10: Scope & Design Cost Control | D10: Critical | E10: Each design Stage | F10: 3.0 › 3.30 Design Cost Control | G10: DCC | H10: PROJ-MCR-CM-DCC-0002_CostCheckAtDesignStage | I10: QS
A11: PC-C-009 | B11: Consultant Appointment and Scope Review | C11: Scope & Design Cost Control | D11: Critical | E11: Pre-construction | F11: 3.0 › 3.40 Consultant Appointments | G11: CNS | H11: PROJ-MCR-CM-CNS-0001_ConsultantAppointmentScopeReview | I11: CA
A12: PC-C-012 | B12: Testing, Commissioning and Performance Requirements Matrix | C12: Scope & Design Cost Control | D12: Critical | E12: Pre-construction | F12: 3.0 › 3.50 Performance & Handover Requirements | G12: PHR | H12: PROJ-MCR-CM-PHR-0001_Testing | I12: PCC
A13: PC-D-001 | B13: Detailed Cost Plan | C13: Cost Planning & Budget | D13: Critical | E13: Pre-construction | F13: 3.0 › 3.60 Cost Baseline | G13: CBL | H13: PROJ-MCR-CM-CBL-0001_DetailedCostPlan | I13: QS
A14: PC-D-003 | B14: Work Breakdown Structure / Cost Breakdown Structure | C14: Cost Planning & Budget | D14: Critical | E14: Pre-construction | F14: 3.0 › 3.70 Cost Coding | G14: COD | H14: PROJ-MCR-CM-COD-0001_WorkBreakdownStructure | I14: PCC
A15: PC-D-004 | B15: Cost Code Structure | C15: Cost Planning & Budget | D15: Critical | E15: Pre-construction | F15: 3.0 › 3.70 Cost Coding | G15: COD | H15: PROJ-MCR-CM-COD-0002_CostCodeStructure | I15: PCC
A16: PC-D-006 | B16: Opening Cost/Value Reconciliation (CVR) | C16: Cost Planning & Budget | D16: Critical | E16: Pre-start | F16: 3.0 › 3.60 Cost Baseline | G16: CBL | H16: PROJ-MCR-CM-CBL-0003_OpeningCost | I16: QS
... A150: PC-F-013 | B150: Unsuccessful Tenderer Close-Out Record | C150: Tendering & Package Award | D150: Low | E150: After award | F150: 4.0 › 4.60 Package Award & Recommendation | G150: PAW | H150: PROJ-MCR-CM-PAW-0008_UnsuccessfulTendererCloseOutRecord | I150: QS

Sheet Pre-Con Folder Structure
A1: Pre-Construction Commercial — Folder Structure
A2: Purpose-built for the pre-construction phase. Naming: PROJ-MCR-CM-[TYPE]-[####]_[Title]. Your construction-phase tree is unchanged.
A4: L1 Code | B4: Level 1 Folder | C4: L2 Code | D4: Level 2 Folder | E4: TYPE | F4: Owner | G4: Items
A5: 0.0 | B5: Admin & Document Control
C6: 0.10 | D6: Commercial Procedures & Protocols | E6: PROC | F6: CA | G6: =COUNTIF('Master Register'!$U$4:$U$178,$C6&" "&$D6) -> 7
C7: 0.20 | D7: Standard Templates | E7: TMP | F7: CA | G7: =COUNTIF('Master Register'!$U$4:$U$178,$C7&" "&$D7) -> 5
C8: 0.30 | D8: DeleStaged Authority & Governance | E8: GOV | F8: CM | G8: =COUNTIF('Master Register'!$U$4:$U$178,$C8&" "&$D8) -> 3
C9: 0.40 | D9: Meetings, Contacts & Decisions | E9: MTG | F9: CA | G9: =COUNTIF('Master Register'!$U$4:$U$178,$C9&" "&$D9) -> 4
A10: 1.0 | B10: Tender & Bid Baseline
C11: 1.10 | D11: Tender Source Information (Frozen) | E11: TSI | F11: QS | G11: =COUNTIF('Master Register'!$U$4:$U$178,$C11&" "&$D11) -> 5
C12: 1.20 | D12: Priced Bid & Assumptions | E12: BID | F12: QS | G12: =COUNTIF('Master Register'!$U$4:$U$178,$C12&" "&$D12) -> 1
C13: 1.30 | D13: Bid Governance & Submission | E13: BGV | F13: QS | G13: =COUNTIF('Master Register'!$U$4:$U$178,$C13&" "&$D13) -> 5
A14: 2.0 | B14: Contract Formation
C15: 2.10 | D15: Executed Contract & Particulars | E15: CON | F15: CM | G15: =COUNTIF('Master Register'!$U$4:$U$178,$C15&" "&$D15) -> 4
C16: 2.20 | D16: Tender-to-Contract Reconciliation | E16: T2C | F16: CM | G16: =COUNTIF('Master Register'!$U$4:$U$178,$C16&" "&$D16) -> 2
C17: 2.30 | D17: Contract Risk & Liabilities | E17: CRL | F17: CM | G17: =COUNTIF('Master Register'!$U$4:$U$178,$C17&" "&$D17) -> 4
C18: 2.40 | D18: ER / CP & Compliance | E18: ERCP | F18: PCC | G18: =COUNTIF('Master Register'!$U$4:$U$178,$C18&" "&$D18) -> 2
C19: 2.50 | D19: Contract Correspondence | E19: CCR | F19: CA | G19: =COUNTIF('Master Register'!$U$4:$U$178,$C19&" "&$D19) -> 0
C20: 2.60 | D20: Contract Pricing Basis | E20: CPB | F20: QS | G20: =COUNTIF('Master Register'!$U$4:$U$178,$C20&" "&$D20) -> 2
A21: 3.0 | B21: Scope, Design & Cost Planning
C22: 3.10 | D22: Scope Definition & Interfaces | E22: SCP | F22: PCC | G22: =COUNTIF('Master Register'!$U$4:$U$178,$C22&" "&$D22) -> 3
C23: 3.20 | D23: Design Management | E23: DSN | F23: PCC | G23: =COUNTIF('Master Register'!$U$4:$U$178,$C23&" "&$D23) -> 1
C24: 3.30 | D24: Design Cost Control | E24: DCC | F24: QS | G24: =COUNTIF('Master Register'!$U$4:$U$178,$C24&" "&$D24) -> 5
C25: 3.40 | D25: Consultant Appointments | E25: CNS | F25: CA | G25: =COUNTIF('Master Register'!$U$4:$U$178,$C25&" "&$D25) -> 2
C26: 3.50 | D26: Performance & Handover Requirements | E26: PHR | F26: PCC | G26: =COUNTIF('Master Register'!$U$4:$U$178,$C26&" "&$D26) -> 2
C27: 3.60 | D27: Cost Baseline | E27: CBL | F27: QS | G27: =COUNTIF('Master Register'!$U$4:$U$178,$C27&" "&$D27) -> 4
C28: 3.70 | D28: Cost Coding | E28: COD | F28: PCC | G28: =COUNTIF('Master Register'!$U$4:$U$178,$C28&" "&$D28) -> 3
C29: 3.80 | D29: Budget Build-Up | E29: BUD | F29: PCC | G29: =COUNTIF('Master Register'!$U$4:$U$178,$C29&" "&$D29) -> 5
C30: 3.90 | D30: Provisional Sums, Contingency & Value | E30: PSV | F30: QS | G30: =COUNTIF('Master Register'!$U$4:$U$178,$C30&" "&$D30) -> 8
A31: 4.0 | B31: Procurement & Package Award
C32: 4.10 | D32: Procurement Strategy & Schedule | E32: PRS | F32: PCC | G32: =COUNTIF('Master Register'!$U$4:$U$178,$C32&" "&$D32) -> 6
C33: 4.20 | D33: Supply Chain Management | E33: SCM | F33: CA | G33: =COUNTIF('Master Register'!$U$4:$U$178,$C33&" "&$D33) -> 7
C34: 4.30 | D34: Responsible Procurement | E34: RSP | F34: PCC | G34: =COUNTIF('Master Register'!$U$4:$U$178,$C34&" "&$D34) -> 2
C35: 4.40 | D35: Package Enquiry | E35: PKE | F35: QS | G35: =COUNTIF('Master Register'!$U$4:$U$178,$C35&" "&$D35) -> 3
C36: 4.50 | D36: Package Tender Analysis | E36: PTA | F36: QS | G36: =COUNTIF('Master Register'!$U$4:$U$178,$C36&" "&$D36) -> 2
C37: 4.60 | D37: Package Award & Recommendation | E37: PAW | F37: QS | G37: =COUNTIF('Master Register'!$U$4:$U$178,$C37&" "&$D37) -> 8
A38: 5.0 | B38: Subcontract Formation
C39: 5.10 | D39: Order Control | E39: SCO | F39: PCC | G39: =COUNTIF('Master Register'!$U$4:$U$178,$C39&" "&$D39) -> 3
C40: 5.20 | D40: Downstream Terms & Flow-Down | E40: SDT | F40: QS | G40: =COUNTIF('Master Register'!$U$4:$U$178,$C40&" "&$D40) -> 2
C41: 5.30 | D41: Security & Insurance | E41: SSI | F41: CA | G41: =COUNTIF('Master Register'!$U$4:$U$178,$C41&" "&$D41) -> 3
...

Sheet Master Register
A1: Pre-Construction Commercial Pack - Extensive Master Register
A3: Ref | B3: Workstream | C3: Subcategory | D3: Document / Control | E3: Purpose / Commercial Risk | F3: Include in Pack? | G3: Status | H3: Priority | I3: Governance Tier | J3: Primary Owner | K3: Contributors | L3: Audience | M3: Stage / Stage | N3: Frequency | O3: Due Date | P3: Current Version | Q3: Storage Link / File Ref | R3: Source / Basis | S3: Notes / Action | T3: Level 1 Folder | U3: Level 2 Folder | V3: TYPE | W3: Proposed File Name | X3: Meridian Owner | Y3: Stage
A4: PC-A-001 | B4: Tender & Bid Baseline | C4: Tender source information | D4: Client ITT / Tender Documents (as issued) | E4: Defines the information and scope actually priced; preserve the complete issue as the tender baseline. | F4: TBC | G4: Not Started | H4: Critical | I4: Tier 2 - Commercial Review | J4: Estimator | K4: Commercial Manager | L4: Internal / Client | M4: Tender receipt | N4: Once | R4: Source Word register | T4: 1.0 Tender & Bid Baseline | U4: 1.10 Tender Source Information (Frozen) | V4: TSI | W4: PROJ-MCR-CM-TSI-0001_ClientITT | X4: QS | Y4: Stage 1 - Bid
A5: PC-A-002 | B5: Tender & Bid Baseline | C5: Tender source information | D5: Tender Addenda / Bulletin Register | E5: Captures every bulletin, revised document and pricing instruction issued during tender. | F5: TBC | G5: Not Started | H5: Critical | I5: Tier 2 - Commercial Review | J5: Estimator | K5: Design Manager; QS | L5: Internal | M5: Tender period | N5: Live during tender | R5: Source Word register | T5: 1.0 Tender & Bid Baseline | U5: 1.10 Tender Source Information (Frozen) | V5: TSI | W5: PROJ-MCR-CM-TSI-0004_TenderAddenda | X5: QS | Y5: Stage 1 - Bid
A6: PC-A-003 | B6: Tender & Bid Baseline | C6: Tender source information | D6: Tender Clarifications and RFI Log | E6: Records queries, responses, assumptions and unanswered matters affecting scope or price. | F6: TBC | G6: Not Started | H6: Critical | I6: Tier 2 - Commercial Review | J6: Estimator | K6: Design Manager; QS | L6: Internal / Client | M6: Tender period | N6: Live during tender | R6: Source Word register | T6: 1.0 Tender & Bid Baseline | U6: 1.10 Tender Source Information (Frozen) | V6: TSI | W6: PROJ-MCR-CM-TSI-0005_TenderClarificationsRFILog | X6: QS | Y6: Stage 1 - Bid
A7: PC-A-004 | B7: Tender & Bid Baseline | C7: Tender source information | D7: Site Visit / Existing Conditions Record | E7: Records visible conditions, access, logistics and constraints relied upon in pricing. | F7: TBC | G7: Not Started | H7: High | I7: Tier 3 - Internal Control | J7: Estimator | K7: Project Manager; Design Manager | L7: Internal | M7: Tender period | N7: Once / each visit | R7: Expanded recommendation | T7: 1.0 Tender & Bid Baseline | U7: 1.10 Tender Source Information (Frozen) | V7: TSI | W7: PROJ-MCR-CM-TSI-0006_SiteVisit | X7: QS | Y7: Stage 1 - Bid
A8: PC-A-005 | B8: Tender & Bid Baseline | C8: Tender source information | D8: Tender Return Requirements Checklist | E8: Controls all mandatory return documents, forms, declarations and submission deadlines. | F8: TBC | G8: Not Started | H8: High | I8: Tier 3 - Internal Control | J8: Estimator | K8: Commercial Manager | L8: Internal | M8: Tender period | N8: Live during tender | R8: Expanded recommendation | T8: 1.0 Tender & Bid Baseline | U8: 1.10 Tender Source Information (Frozen) | V8: TSI | W8: PROJ-MCR-CM-TSI-0007_TenderReturnRequirementsChecklist | X8: QS | Y8: Stage 1 - Bid
A9: PC-A-006 | B9: Tender & Bid Baseline | C9: Tender source information | D9: Priced Tender Submission (full build-up) | E9: Preserves the submitted price, quantities, rates, resource assumptions and allowances. | F9: TBC | G9: Not Started | H9: Critical | I9: Tier 2 - Commercial Review | J9: Estimator | K9: QS; Commercial Manager | L9: Internal | M9: Tender submission | N9: Once | R9: Source Word register | T9: 1.0 Tender & Bid Baseline | U9: 1.20 Priced Bid & Assumptions | V9: BID | W9: PROJ-MCR-CM-BID-0001_PricedTenderSubmission | X9: QS | Y9: Stage 1 - Bid
A10: PC-A-007 | B10: Tender & Bid Baseline | C10: Tender source information | D10: Tender Qualifications, Exclusions and Assumptions Schedule | E10: Primary record of items included, excluded or qualified; must be carried into the contract. | F10: TBC | G10: Not Started | H10: Critical | I10: Tier 1 - Board / Client Visibility | J10: Commercial Manager | K10: Estimator; Legal | L10: Internal / Client | M10: Tender submission | N10: Update through negotiation | R10: Both source lists | T10: 1.0 Tender & Bid Baseline | U10: 1.30 Bid Governance & Submission | V10: BGV | W10: PROJ-MCR-CM-BGV-0001_TenderQualifications | X10: QS | Y10: Stage 1 - Bid
A11: PC-A-008 | B11: Tender & Bid Baseline | C11: Tender source information | D11: Tender Baseline Programme | E11: Records the duration, sequencing, access and procurement assumptions underpinning the price. | F11: TBC | G11: Not Started | H11: Critical | I11: Tier 2 - Commercial Review | J11: Planner | K11: Commercial Manager; Project Manager | L11: Internal / Client | M11: Tender submission | N11: Once / agreed revision | R11: Source Word register | T11: 1.0 Tender & Bid Baseline | U11: 1.30 Bid Governance & Submission | V11: BGV | W11: PROJ-MCR-CM-BGV-0002_TenderBaselineProgramme | X11: QS | Y11: Stage 1 - Bid
A12: PC-A-009 | B12: Tender & Bid Baseline | C12: Tender source information | D12: Tender Adjudication / Settlement Summary | E12: Formal internal approval of price, margin, risk, qualifications and authority to submit. | F12: TBC | G12: Not Started | H12: Critical | I12: Tier 1 - Board / Client Visibility | J12: Commercial Director | K12: Commercial Manager; Estimator | L12: Board / Internal | M12: Tender submission | N12: Once | R12: Source Word register | T12: 1.0 Tender & Bid Baseline | U12: 1.30 Bid Governance & Submission | V12: BGV | W12: PROJ-MCR-CM-BGV-0003_TenderAdjudication | X12: QS | Y12: Stage 1 - Bid
A13: PC-A-010 | B13: Tender & Bid Baseline | C13: Tender source information | D13: Tender Risk and Opportunity Schedule | E13: Quantifies bid risks, opportunities, owners, mitigations and allowances included in the tender. | F13: TBC | G13: Not Started | H13: Critical | I13: Tier 1 - Board / Client Visibility | J13: Commercial Manager | K13: Estimator; Project Manager | L13: Board / Internal | M13: Tender submission | N13: Update through negotiation | R13: Expanded recommendation | T13: 1.0 Tender & Bid Baseline | U13: 1.30 Bid Governance & Submission | V13: BGV | W13: PROJ-MCR-CM-BGV-0004_TenderRiskOpportunitySchedule | X13: QS | Y13: Stage 1 - Bid
A14: PC-A-011 | B14: Tender & Bid Baseline | C14: Tender source information | D14: Bid Bonds / Tender Security Record | E14: Confirms any tender bond, validity period, wording and release requirements. | F14: TBC | G14: Not Started | H14: High | I14: Tier 3 - Internal Control | J14: Commercial Manager | K14: Finance; Legal | L14: Internal | M14: Tender submission | N14: Once | R14: Expanded recommendation | T14: 1.0 Tender & Bid Baseline | U14: 1.30 Bid Governance & Submission | V14: BGV | W14: PROJ-MCR-CM-BGV-0005_BidBonds | X14: QS | Y14: Stage 1 - Bid
A15: PC-B-001 | B15: Contract Formation | C15: Main contract and appointments | D15: Contract-vs-Tender Reconciliation | E15: Identifies every movement between tender and signed deal, including qualifications that were lost or amended. | F15: TBC | G15: Not Started | H15: Critical | I15: Tier 1 - Board / Client Visibility | J15: Commercial Manager | K15: Estimator; Legal | L15: Board / Internal | M15: Pre-contract | N15: Once before execution | R15: Source Word register | T15: 2.0 Contract Formation | U15: 2.20 Tender-to-Contract Reconciliation | V15: T2C | W15: PROJ-MCR-CM-T2C-0001_ContractVsTenderReconciliation | X15: CM | Y15: Stage 2 - Award
... A178: PC-O-014 | B178: Mobilisation & Delivery Handover | C178: Pre-construction completion | D178: Commercial Pack Approval and Issue Record | E178: Records reviewer, approval date, revision and controlled issue of the pre-construction pack. | F178: TBC | G178: Not Started | H178: Critical | I178: Tier 1 - Board / Client Visibility | J178: Commercial Director | K178: Commercial Manager; Document Controller | L178: Board / Internal | M178: Pre-start Stage | N178: Once / revision | R178: Expanded recommendation | T178: 12.0 Mobilisation & Pre-Start Handover | U178: 12.10 Commercial Readiness | V178: RDY | W178: PROJ-MCR-CM-RDY-0005_CommercialPackApprovalIssueRecord | X178: CM | Y178: Stage 3 - Pre-Con

Sheet Folder Coverage
A1: Folder Coverage — items per Level 1 folder
A3: L1 Code | B3: Level 1 Folder | C3: Items
A4: 0.0 | B4: Admin & Document Control | C4: =COUNTIF('Master Register'!$T$4:$T$178,$A4&" "&$B4) -> 19
A5: 1.0 | B5: Tender & Bid Baseline | C5: =COUNTIF('Master Register'!$T$4:$T$178,$A5&" "&$B5) -> 11
A6: 2.0 | B6: Contract Formation | C6: =COUNTIF('Master Register'!$T$4:$T$178,$A6&" "&$B6) -> 14
A7: 3.0 | B7: Scope, Design & Cost Planning | C7: =COUNTIF('Master Register'!$T$4:$T$178,$A7&" "&$B7) -> 33
A8: 4.0 | B8: Procurement & Package Award | C8: =COUNTIF('Master Register'!$T$4:$T$178,$A8&" "&$B8) -> 28
A9: 5.0 | B9: Subcontract Formation | C9: =COUNTIF('Master Register'!$T$4:$T$178,$A9&" "&$B9) -> 9
A10: 6.0 | B10: Cashflow, Payment & Tax | C10: =COUNTIF('Master Register'!$T$4:$T$178,$A10&" "&$B10) -> 5
A11: 7.0 | B11: Risk, Governance & Entitlement | C11: =COUNTIF('Master Register'!$T$4:$T$178,$A11&" "&$B11) -> 12
A12: 8.0 | B12: Programme & Delay Commercials | C12: =COUNTIF('Master Register'!$T$4:$T$178,$A12&" "&$B12) -> 5
A13: 9.0 | B13: Insurance, Security & Warranties | C13: =COUNTIF('Master Register'!$T$4:$T$178,$A13&" "&$B13) -> 9
A14: 10.0 | B14: Property, Statutory & Third Parties | C14: =COUNTIF('Master Register'!$T$4:$T$178,$A14&" "&$B14) -> 12
A15: 11.0 | B15: Commercial Reporting & Controls | C15: =COUNTIF('Master Register'!$T$4:$T$178,$A15&" "&$B15) -> 4
A16: 12.0 | B16: Mobilisation & Pre-Start Handover | C16: =COUNTIF('Master Register'!$T$4:$T$178,$A16&" "&$B16) -> 14
B17: TOTAL | C17: =SUM(C4:C16) -> 175

Sheet Dashboard
A1: Pre-Construction Commercial Pack - Control Dashboard
A2: Extensive master checklist. Set “Include in Pack?” to Yes / No after project review; do not treat every item as automatically applicable.
A4: Control | B4: Count | D4: Progress | E4: Result | G4: Stage | H4: Documents
A5: Total documents | B5: =COUNTA('Master Register'!$A$4:$A$178) -> 175 | D5: Applicability reviewed | E5: =IF(B5=0,0,(B6+B7)/B5) -> 0 | G5: Stage 1 - Bid | H5: =COUNTIF('Master Register'!$Y$4:$Y$178,G5) -> 11
A6: Included - Yes | B6: =COUNTIF('Master Register'!$F$4:$F$178,"Yes") -> 0 | D6: Completed | E6: =COUNTIF('Master Register'!$G$4:$G$178,"Complete") -> 0 | G6: Stage 2 - Award | H6: =COUNTIF('Master Register'!$Y$4:$Y$178,G6) -> 19
A7: Excluded - No | B7: =COUNTIF('Master Register'!$F$4:$F$178,"No") -> 0 | D7: In progress | E7: =COUNTIF('Master Register'!$G$4:$G$178,"In Progress") -> 0 | G7: Stage 3 - Pre-Con | H7: =COUNTIF('Master Register'!$Y$4:$Y$178,G7) -> 145
A8: Still TBC | B8: =COUNTIF('Master Register'!$F$4:$F$178,"TBC") -> 175 | D8: Overdue open items | E8: =COUNTIFS('Master Register'!$O$4:$O$178,"<"&TODAY(),'Master Register'!$O$4:$O$178,"<>",'Master Register'!$G$4:$G$178,"<>Complete",'Master Register'!$F$4:$F$178,"<>No") -> 0 | G8: TOTAL | H8: =SUM(H5:H7) -> 175
A9: Critical priority | B9: =COUNTIF('Master Register'!$H$4:$H$178,"Critical") -> 91 | D9: Source items retained | E9: =COUNTIF('Master Register'!$R$4:$R$178,"<>Expanded recommendation") -> 72
A12: Workstream | B12: Total | C12: Include Yes | D12: Still TBC
A13: Tender & Bid Baseline | B13: =COUNTIF('Master Register'!$B$4:$B$178,A13) -> 11 | C13: =COUNTIFS('Master Register'!$B$4:$B$178,A13,'Master Register'!$F$4:$F$178,"Yes") -> 0 | D13: =COUNTIFS('Master Register'!$B$4:$B$178,A13,'Master Register'!$F$4:$F$178,"TBC") -> 11
A14: Contract Formation | B14: =COUNTIF('Master Register'!$B$4:$B$178,A14) -> 14 | C14: =COUNTIFS('Master Register'!$B$4:$B$178,A14,'Master Register'!$F$4:$F$178,"Yes") -> 0 | D14: =COUNTIFS('Master Register'!$B$4:$B$178,A14,'Master Register'!$F$4:$F$178,"TBC") -> 14
A15: Scope & Design Cost Control | B15: =COUNTIF('Master Register'!$B$4:$B$178,A15) -> 13 | C15: =COUNTIFS('Master Register'!$B$4:$B$178,A15,'Master Register'!$F$4:$F$178,"Yes") -> 0 | D15: =COUNTIFS('Master Register'!$B$4:$B$178,A15,'Master Register'!$F$4:$F$178,"TBC") -> 13
A16: Cost Planning & Budget | B16: =COUNTIF('Master Register'!$B$4:$B$178,A16) -> 20 | C16: =COUNTIFS('Master Register'!$B$4:$B$178,A16,'Master Register'!$F$4:$F$178,"Yes") -> 0 | D16: =COUNTIFS('Master Register'!$B$4:$B$178,A16,'Master Register'!$F$4:$F$178,"TBC") -> 20
A17: Procurement Strategy | B17: =COUNTIF('Master Register'!$B$4:$B$178,A17) -> 15 | C17: =COUNTIFS('Master Register'!$B$4:$B$178,A17,'Master Register'!$F$4:$F$178,"Yes") -> 0 | D17: =COUNTIFS('Master Register'!$B$4:$B$178,A17,'Master Register'!$F$4:$F$178,"TBC") -> 15
A18: Tendering & Package Award | B18: =COUNTIF('Master Register'!$B$4:$B$178,A18) -> 13 | C18: =COUNTIFS('Master Register'!$B$4:$B$178,A18,'Master Register'!$F$4:$F$178,"Yes") -> 0 | D18: =COUNTIFS('Master Register'!$B$4:$B$178,A18,'Master Register'!$F$4:$F$178,"TBC") -> 13
A19: Subcontract Formation | B19: =COUNTIF('Master Register'!$B$4:$B$178,A19) -> 10 | C19: =COUNTIFS('Master Register'!$B$4:$B$178,A19,'Master Register'!$F$4:$F$178,"Yes") -> 0 | D19: =COUNTIFS('Master Register'!$B$4:$B$178,A19,'Master Register'!$F$4:$F$178,"TBC") -> 10
A20: Cashflow, Payment & Tax | B20: =COUNTIF('Master Register'!$B$4:$B$178,A20) -> 7 | C20: =COUNTIFS('Master Register'!$B$4:$B$178,A20,'Master Register'!$F$4:$F$178,"Yes") -> 0 | D20: =COUNTIFS('Master Register'!$B$4:$B$178,A20,'Master Register'!$F$4:$F$178,"TBC") -> 7
A21: Risk, Opportunity & Governance | B21: =COUNTIF('Master Register'!$B$4:$B$178,A21) -> 9 | C21: =COUNTIFS('Master Register'!$B$4:$B$178,A21,'Master Register'!$F$4:$F$178,"Yes") -> 0 | D21: =COUNTIFS('Master Register'!$B$4:$B$178,A21,'Master Register'!$F$4:$F$178,"TBC") -> 9
A22: Change, Claims & Entitlement | B22: =COUNTIF('Master Register'!$B$4:$B$178,A22) -> 9 | C22: =COUNTIFS('Master Register'!$B$4:$B$178,A22,'Master Register'!$F$4:$F$178,"Yes") -> 0 | D22: =COUNTIFS('Master Register'!$B$4:$B$178,A22,'Master Register'!$F$4:$F$178,"TBC") -> 9
A23: Programme & Delay Commercials | B23: =COUNTIF('Master Register'!$B$4:$B$178,A23) -> 6 | C23: =COUNTIFS('Master Register'!$B$4:$B$178,A23,'Master Register'!$F$4:$F$178,"Yes") -> 0 | D23: =COUNTIFS('Master Register'!$B$4:$B$178,A23,'Master Register'!$F$4:$F$178,"TBC") -> 6
A24: Insurance, Security & Warranties | B24: =COUNTIF('Master Register'!$B$4:$B$178,A24) -> 9 | C24: =COUNTIFS('Master Register'!$B$4:$B$178,A24,'Master Register'!$F$4:$F$178,"Yes") -> 0 | D24: =COUNTIFS('Master Register'!$B$4:$B$178,A24,'Master Register'!$F$4:$F$178,"TBC") -> 9
... A27: Mobilisation & Delivery Handover | B27: =COUNTIF('Master Register'!$B$4:$B$178,A27) -> 14 | C27: =COUNTIFS('Master Register'!$B$4:$B$178,A27,'Master Register'!$F$4:$F$178,"Yes") -> 0 | D27: =COUNTIFS('Master Register'!$B$4:$B$178,A27,'Master Register'!$F$4:$F$178,"TBC") -> 14
A28: Workstream | B28: Stage 1 - Bid | C28: Stage 2 - Award | D28: Stage 3 - Pre-Con | E28: Total | G28: DOCUMENTS BY WORKSTREAM AND STAGE
A29: =A13 -> Tender & Bid Baseline | B29: =COUNTIFS('Master Register'!$B$4:$B$178,$A29,'Master Register'!$Y$4:$Y$178,B$28) -> 11 | C29: =COUNTIFS('Master Register'!$B$4:$B$178,$A29,'Master Register'!$Y$4:$Y$178,C$28) -> 0 | D29: =COUNTIFS('Master Register'!$B$4:$B$178,$A29,'Master Register'!$Y$4:$Y$178,D$28) -> 0 | E29: =SUM(B29:D29) -> 11
A30: =A14 -> Contract Formation | B30: =COUNTIFS('Master Register'!$B$4:$B$178,$A30,'Master Register'!$Y$4:$Y$178,B$28) -> 0 | C30: =COUNTIFS('Master Register'!$B$4:$B$178,$A30,'Master Register'!$Y$4:$Y$178,C$28) -> 14 | D30: =COUNTIFS('Master Register'!$B$4:$B$178,$A30,'Master Register'!$Y$4:$Y$178,D$28) -> 0 | E30: =SUM(B30:D30) -> 14
A31: =A15 -> Scope & Design Cost Control | B31: =COUNTIFS('Master Register'!$B$4:$B$178,$A31,'Master Register'!$Y$4:$Y$178,B$28) -> 0 | C31: =COUNTIFS('Master Register'!$B$4:$B$178,$A31,'Master Register'!$Y$4:$Y$178,C$28) -> 0 | D31: =COUNTIFS('Master Register'!$B$4:$B$178,$A31,'Master Register'!$Y$4:$Y$178,D$28) -> 13 | E31: =SUM(B31:D31) -> 13
A32: =A16 -> Cost Planning & Budget | B32: =COUNTIFS('Master Register'!$B$4:$B$178,$A32,'Master Register'!$Y$4:$Y$178,B$28) -> 0 | C32: =COUNTIFS('Master Register'!$B$4:$B$178,$A32,'Master Register'!$Y$4:$Y$178,C$28) -> 2 | D32: =COUNTIFS('Master Register'!$B$4:$B$178,$A32,'Master Register'!$Y$4:$Y$178,D$28) -> 18 | E32: =SUM(B32:D32) -> 20
A33: =A17 -> Procurement Strategy | B33: =COUNTIFS('Master Register'!$B$4:$B$178,$A33,'Master Register'!$Y$4:$Y$178,B$28) -> 0 | C33: =COUNTIFS('Master Register'!$B$4:$B$178,$A33,'Master Register'!$Y$4:$Y$178,C$28) -> 0 | D33: =COUNTIFS('Master Register'!$B$4:$B$178,$A33,'Master Register'!$Y$4:$Y$178,D$28) -> 15 | E33: =SUM(B33:D33) -> 15
A34: =A18 -> Tendering & Package Award | B34: =COUNTIFS('Master Register'!$B$4:$B$178,$A34,'Master Register'!$Y$4:$Y$178,B$28) -> 0 | C34: =COUNTIFS('Master Register'!$B$4:$B$178,$A34,'Master Register'!$Y$4:$Y$178,C$28) -> 0 | D34: =COUNTIFS('Master Register'!$B$4:$B$178,$A34,'Master Register'!$Y$4:$Y$178,D$28) -> 13 | E34: =SUM(B34:D34) -> 13
A35: =A19 -> Subcontract Formation | B35: =COUNTIFS('Master Register'!$B$4:$B$178,$A35,'Master Register'!$Y$4:$Y$178,B$28) -> 0 | C35: =COUNTIFS('Master Register'!$B$4:$B$178,$A35,'Master Register'!$Y$4:$Y$178,C$28) -> 0 | D35: =COUNTIFS('Master Register'!$B$4:$B$178,$A35,'Master Register'!$Y$4:$Y$178,D$28) -> 10 | E35: =SUM(B35:D35) -> 10
A36: =A20 -> Cashflow, Payment & Tax | B36: =COUNTIFS('Master Register'!$B$4:$B$178,$A36,'Master Register'!$Y$4:$Y$178,B$28) -> 0 | C36: =COUNTIFS('Master Register'!$B$4:$B$178,$A36,'Master Register'!$Y$4:$Y$178,C$28) -> 2 | D36: =COUNTIFS('Master Register'!$B$4:$B$178,$A36,'Master Register'!$Y$4:$Y$178,D$28) -> 5 | E36: =SUM(B36:D36) -> 7
A37: =A21 -> Risk, Opportunity & Governance | B37: =COUNTIFS('Master Register'!$B$4:$B$178,$A37,'Master Register'!$Y$4:$Y$178,B$28) -> 0 | C37: =COUNTIFS('Master Register'!$B$4:$B$178,$A37,'Master Register'!$Y$4:$Y$178,C$28) -> 0 | D37: =COUNTIFS('Master Register'!$B$4:$B$178,$A37,'Master Register'!$Y$4:$Y$178,D$28) -> 9 | E37: =SUM(B37:D37) -> 9
A38: =A22 -> Change, Claims & Entitlement | B38: =COUNTIFS('Master Register'!$B$4:$B$178,$A38,'Master Register'!$Y$4:$Y$178,B$28) -> 0 | C38: =COUNTIFS('Master Register'!$B$4:$B$178,$A38,'Master Register'!$Y$4:$Y$178,C$28) -> 0 | D38: =COUNTIFS('Master Register'!$B$4:$B$178,$A38,'Master Register'!$Y$4:$Y$178,D$28) -> 9 | E38: =SUM(B38:D38) -> 9
A39: =A23 -> Programme & Delay Commercials | B39: =COUNTIFS('Master Register'!$B$4:$B$178,$A39,'Master Register'!$Y$4:$Y$178,B$28) -> 0 | C39: =COUNTIFS('Master Register'!$B$4:$B$178,$A39,'Master Register'!$Y$4:$Y$178,C$28) -> 0 | D39: =COUNTIFS('Master Register'!$B$4:$B$178,$A39,'Master Register'!$Y$4:$Y$178,D$28) -> 6 | E39: =SUM(B39:D39) -> 6
A40: =A24 -> Insurance, Security & Warranties | B40: =COUNTIFS('Master Register'!$B$4:$B$178,$A40,'Master Register'!$Y$4:$Y$178,B$28) -> 0 | C40: =COUNTIFS('Master Register'!$B$4:$B$178,$A40,'Master Register'!$Y$4:$Y$178,C$28) -> 0 | D40: =COUNTIFS('Master Register'!$B$4:$B$178,$A40,'Master Register'!$Y$4:$Y$178,D$28) -> 9 | E40: =SUM(B40:D40) -> 9
... A43: =A27 -> Mobilisation & Delivery Handover | B43: =COUNTIFS('Master Register'!$B$4:$B$178,$A43,'Master Register'!$Y$4:$Y$178,B$28) -> 0 | C43: =COUNTIFS('Master Register'!$B$4:$B$178,$A43,'Master Register'!$Y$4:$Y$178,C$28) -> 0 | D43: =COUNTIFS('Master Register'!$B$4:$B$178,$A43,'Master Register'!$Y$4:$Y$178,D$28) -> 14 | E43: =SUM(B43:D43) -> 14

Sheet Guidance & Lookups
A1: How to Use This Register | J1: Owner Lookup
J2: Commercial Director
A3: Field | B3: Required use | C3: Do not do | D3: Control owner | F3: Pre-start minimum Stage | G3: Why | H3: Owner | J3: Commercial Manager
A4: Include in Pack? | B4: Set Yes, No or TBC after contract and project review. | C4: Do not leave Critical items at TBC when mobilising. | D4: Commercial Manager | F4: Executed contract or controlled LOI | G4: No work beyond authorised scope/value. | H4: Commercial Director | J4: QS
A5: Status | B5: Record progress of included items. | C5: Do not use Complete unless approved evidence is filed. | D5: Document owner | F5: Tender-to-contract reconciliation | G5: No lost qualification or silent scope movement. | H5: Commercial Manager | J5: Estimator
A6: Priority | B6: Use Critical for controls whose absence creates immediate entitlement, cash or commitment exposure. | C6: Do not downgrade to hide overdue work. | D6: Commercial Manager | F6: Opening CVR and cashflow approved | G6: Margin and funding baseline agreed. | H6: Commercial Manager / Finance | J6: Procurement
A7: Due Date | B7: Link to the actual contract, procurement or mobilisation Stage. | C7: Do not use arbitrary dates disconnected from programme. | D7: Document owner | F7: Risk and entitlement registers live | G7: Exposure and recovery actions allocated. | H7: Commercial Manager | J7: Planner
A8: Storage Link / File Ref | B8: Enter controlled CDE path, SharePoint link or document number. | C8: Do not rely on personal inboxes or local drives. | D8: Document Controller | F8: Payment and notice calendars live | G8: No missed statutory or contractual deadlines. | H8: QS | J8: Project Manager
A9: Notes / Action | B9: Record exclusion rationale, missing inputs, decision required and next action. | C9: Do not write “N/A” without a reason. | D9: Document owner | F9: Procurement and long-lead schedules aligned | G9: Packages can meet programme dates. | H9: Planner / QS | J9: Project Director
A10: Source / Basis | B10: Shows whether the item came from the supplied registers or was added as an expanded recommendation. | C10: Do not treat source status as proof of applicability. | D10: Commercial Manager | F10: Critical orders executed | G10: No uninsured or unauthorised mobilisation. | H10: Commercial Manager | J10: Design Manager
F11: Scope and design interfaces allocated | G11: No package gaps or duplicated allowances. | H11: Design Manager / QS | J11: Document Controller
F12: Commercial handover complete | G12: Delivery team understands the priced position. | H12: Commercial Manager | J12: Finance
A13: Governance Tier | B13: Primary audience | C13: Purpose | D13: Typical content | J13: Legal
A14: Tier 1 - Board / Client Visibility | B14: Board, client, funder or executive approval | C14: Material financial exposure, approvals and external governance. | D14: Contract, cost reports, risk, cash, major awards, security. | J14: H&S
A15: Tier 2 - Commercial Review | B15: Commercial manager, monitoring surveyor, project leadership | C15: Detailed review evidence supporting value, risk and entitlement. | D15: Cost plans, tender analysis, scope comparison, change and forecasts. | J15: MEP Manager
A16: Tier 3 - Internal Control | B16: Meridian project and support teams | C16: Internal control, audit trail and day-to-day administration. | D16: Trackers, calendars, templates, filing and authority controls. | J16: Civils Manager
J17: Environmental Lead
J18: Sustainability Lead
J19: BIM Manager
J20: Temporary Works Coordinator
